<?xml version="1.0" encoding="utf-8"?>
<!-- This URDF was automatically created by SolidWorks to URDF Exporter! Originally created by Stephen Brawner (brawner@gmail.com) 
     Commit Version: 1.6.0-4-g7f85cfe  Build Version: 1.6.7995.38578
     For more information, please see http://wiki.ros.org/sw_urdf_exporter -->
<robot xmlns:xacro="http://www.ros.org/wiki/xacro" name="robotic_arm">

  <link name="world" />
	<joint name="base_joint" type="fixed">
		<parent link="world" />
		<child link="base_link" />
		<origin rpy="0 0 3.142" xyz="0.0 0.0 0.0" />
	</joint>
  <link
    name="base_link">
    <inertial>
      <origin
        xyz="-2.54822930811915E-09 0.00606244117318527 0.0439273833673697"
        rpy="0 0 0" />
      <mass
        value="0.563134616214546" />
      <inertia
        ixx="0.00235189965302231"
        ixy="-7.03692630475745E-10"
        ixz="-2.36827318554001E-12"
        iyy="0.00234682358725741"
        iyz="-0.000111872512052699"
        izz="0.00324785127223651" />
    </inertial>
    <visual>
      <origin
        xyz="0 0 0"
        rpy="0 0 0" />
      <geometry>
        <mesh
          filename="file:///home/brains/Desktop/robotic_arm/src/robotic_arm/meshes/base_link.STL" />
      </geometry>
      <material
        name="">
        <color
          rgba="0.792156862745098 0.819607843137255 0.933333333333333 1" />
      </material>
    </visual>
    <collision>
      <origin
        xyz="0 0 0"
        rpy="0 0 0" />
      <geometry>
        <mesh
          filename="file:///home/brains/Desktop/robotic_arm/src/robotic_arm/meshes/base_link.STL" />
      </geometry>
    </collision>
  </link>
  <link
    name="link_1">
    <inertial>
      <origin
        xyz="0.0653578188339992 0.0020565549859432 0.0762669833315888"
        rpy="0 0 0" />
      <mass
        value="1.45594336973745" />
      <inertia
        ixx="0.00750010742841235"
        ixy="-6.70723882397028E-05"
        ixz="-0.00600095399245133"
        iyy="0.0145423964972034"
        iyz="-8.19377169668812E-05"
        izz="0.00867931656150517" />
    </inertial>
    <visual>
      <origin
        xyz="0 0 0"
        rpy="0 0 0" />
      <geometry>
        <mesh
          filename="file:///home/brains/Desktop/robotic_arm/src/robotic_arm/meshes/link_1.STL" />
      </geometry>
      <material
        name="">
        <color
          rgba="0.792156862745098 0.819607843137255 0.933333333333333 1" />
      </material>
    </visual>
    <collision>
      <origin
        xyz="0 0 0"
        rpy="0 0 0" />
      <geometry>
        <mesh
          filename="file:///home/brains/Desktop/robotic_arm/src/robotic_arm/meshes/link_1.STL" />
      </geometry>
    </collision>
  </link>
  <joint
    name="joint_1"
    type="revolute">
    <origin
      xyz="0 0 0.1285"
      rpy="0 0 0" />
    <parent
      link="base_link" />
    <child
      link="link_1" />
    <axis
      xyz="0 0 1" />
    <limit
      lower="-3.1416"
      upper="3.1416"
      effort="300"
      velocity="3" />
  </joint>
  <link
    name="link_2">
    <inertial>
      <origin
        xyz="0.101431964558784 0.0160412048867569 0.0526572060471867"
        rpy="0 0 0" />
      <mass
        value="0.680974186241497" />
      <inertia
        ixx="0.00235135787645393"
        ixy="5.5007725153141E-05"
        ixz="-0.00380698989134493"
        iyy="0.00992615920208125"
        iyz="2.85566303155651E-05"
        izz="0.0077083015658875" />
    </inertial>
    <visual>
      <origin
        xyz="0 0 0"
        rpy="0 0 0" />
      <geometry>
        <mesh
          filename="file:///home/brains/Desktop/robotic_arm/src/robotic_arm/meshes/link_2.STL" />
      </geometry>
      <material
        name="">
        <color
          rgba="0.792156862745098 0.819607843137255 0.933333333333333 1" />
      </material>
    </visual>
    <collision>
      <origin
        xyz="0 0 0"
        rpy="0 0 0" />
      <geometry>
        <mesh
          filename="file:///home/brains/Desktop/robotic_arm/src/robotic_arm/meshes/link_2.STL" />
      </geometry>
    </collision>
  </link>
  <joint
    name="joint_2"
    type="revolute">
    <origin
      xyz="0.15 0.027 0.152"
      rpy="0 0 0" />
    <parent
      link="link_1" />
    <child
      link="link_2" />
    <axis
      xyz="0 -1 0" />
    <limit
      lower="-1.5"
      upper="1.5708"
      effort="300"
      velocity="3" />
  </joint>
  <link
    name="link_3">
    <inertial>
      <origin
        xyz="0.0298064804142811 -0.0415786769402245 0.0333315004867772"
        rpy="0 0 0" />
      <mass
        value="0.778186643162039" />
      <inertia
        ixx="0.00063905283079692"
        ixy="2.13657560744369E-05"
        ixz="2.72110765072652E-06"
        iyy="0.0029678296765164"
        iyz="3.4710391514597E-05"
        izz="0.00298767359266443" />
    </inertial>
    <visual>
      <origin
        xyz="0 0 0"
        rpy="0 0 0" />
      <geometry>
        <mesh
          filename="file:///home/brains/Desktop/robotic_arm/src/robotic_arm/meshes/link_3.STL" />
      </geometry>
      <material
        name="">
        <color
          rgba="0.792156862745098 0.819607843137255 0.933333333333333 1" />
      </material>
    </visual>
    <collision>
      <origin
        xyz="0 0 0"
        rpy="0 0 0" />
      <geometry>
        <mesh
          filename="file:///home/brains/Desktop/robotic_arm/src/robotic_arm/meshes/link_3.STL" />
      </geometry>
    </collision>
  </link>
  <joint
    name="joint_3"
    type="revolute">
    <origin
      xyz="0.26626 0 0.13822"
      rpy="0 0 0" />
    <parent
      link="link_2" />
    <child
      link="link_3" />
    <axis
      xyz="0 -1 0" />
    <limit
      lower="-2.2"
      upper="3.1"
      effort="300"
      velocity="3" />
  </joint>
  <link
    name="link_4">
    <inertial>
      <origin
        xyz="0.0888627632061177 0.00134563154756934 0.000588329964855916"
        rpy="0 0 0" />
      <mass
        value="0.835937225112789" />
      <inertia
        ixx="0.000558048680532432"
        ixy="-5.59329476734029E-05"
        ixz="-9.48124558843511E-06"
        iyy="0.00246862786118713"
        iyz="3.14125819201248E-06"
        izz="0.00244253536572425" />
    </inertial>
    <visual>
      <origin
        xyz="0 0 0"
        rpy="0 0 0" />
      <geometry>
        <mesh
          filename="file:///home/brains/Desktop/robotic_arm/src/robotic_arm/meshes/link_4.STL" />
      </geometry>
      <material
        name="">
        <color
          rgba="0.792156862745098 0.819607843137255 0.933333333333333 1" />
      </material>
    </visual>
    <collision>
      <origin
        xyz="0 0 0"
        rpy="0 0 0" />
      <geometry>
        <mesh
          filename="file:///home/brains/Desktop/robotic_arm/src/robotic_arm/meshes/link_4.STL" />
      </geometry>
    </collision>
  </link>
  <joint
    name="joint_4"
    type="revolute">
    <origin
      xyz="0.204 -0.0425 0.035"
      rpy="0 0 0" />
    <parent
      link="link_3" />
    <child
      link="link_4" />
    <axis
      xyz="-1 0 0" />
    <limit
      lower="-3.1416"
      upper="3.1416"
      effort="300"
      velocity="3" />
  </joint>
</robot>